<?xml version = "1.0" ?>
<robot
  name="epuck2" xmlns:xacro="http://ros.org/wiki/xacro">
  
 <xacro:include filename="Epuck2.gazebo"/> 
  
<link name="base_link"/>

  <joint name= "base_link_to_main_body" type = "fixed">
   <parent link = "base_link"/>
   <child link = "main_body"/>
  </joint>


  <link
    name="main_body">
    <inertial>
      <origin
        xyz="9.0274E-05 -0.00041659 0.019845"
        rpy="0 0 0" />
      <mass
        value="0.063515" />
      <inertia
        ixx="3.2227E-05"
        ixy="-2.691E-07"
        ixz="4.7122E-08"
        iyy="2.4227E-05"
        iyz="-1.2861E-06"
        izz="3.3868E-05" />
    </inertial>
    <visual>
      <origin
        xyz="0 0 0"
        rpy="0 0 0" />
      <geometry>
        <mesh
          filename="package://epuck_description/meshes/main_body.STL" />
      </geometry>
    </visual>
    <collision>
      <origin
        xyz="0 0 0"
        rpy="0 0 0" />
      <geometry>
        <mesh
          filename="package://epuck_description/meshes/main_body.STL" />
      </geometry>
    </collision>
  </link>
  
  <link
    name="left_wheel">
    <inertial>
      <origin
        xyz="-0.00048709 -3.5245E-18 2.4286E-17"
        rpy="0 0 0" />
      <mass
        value="0.0040981" />
      <inertia
        ixx="8.267E-07"
        ixy="-9.8761E-23"
        ixz="-8.6429E-13"
        iyy="4.304E-07"
        iyz="-2.3376E-22"
        izz="4.304E-07" />
    </inertial>
    <visual>
      <origin
        xyz="0 0 0"
        rpy="0 0 0" />
      <geometry>
        <mesh
          filename="package://epuck_description/meshes/left_wheel.STL" />
      </geometry>
    </visual>
    <collision>
      <origin
        xyz="0 0 0"
        rpy="0 0 0" />
      <geometry>
        <mesh
          filename="package://epuck_description/meshes/left_wheel.STL" />
      </geometry>
    </collision>
  </link>
  
  <joint
    name="left_joint"
    type="continuous">
    <origin
      xyz="0.0278 0 0.02"
      rpy="0 0 0" />
    <parent
      link="main_body" />
    <child
      link="left_wheel" />
    <axis
      xyz="1 0 0" />
    <limit
      effort="0.001"
      velocity="10" />
  </joint>
  <link
    name="right_wheel">

    <inertial>
      <origin
        xyz="0.00065056 4.0415E-18 7.2858E-17"
        rpy="0 0 0" />
      <mass
        value="0.0038059" />
      <inertia
        ixx="8.2274E-07"
        ixy="-1.0753E-22"
        ixz="8.6429E-13"
        iyy="4.2585E-07"
        iyz="2.3307E-22"
        izz="4.2585E-07" />
    </inertial>
    <visual>
      <origin
        xyz="0 0 0"
        rpy="0 0 0" />
      <geometry>
        <mesh
          filename="package://epuck_description/meshes/right_wheel.STL" />
      </geometry>
    </visual>
    <collision>
      <origin
        xyz="0 0 0"
        rpy="0 0 0" />
      <geometry>
        <mesh
          filename="package://epuck_description/meshes/right_wheel.STL" />
      </geometry>
    </collision>
  </link>
  
<joint
    name="right_joint"
    type="continuous">
    <origin
      xyz="-0.0278 0 0.02"
      rpy="0 0 0" />
    <parent
      link="main_body" />
    <child
      link="right_wheel" />
    <axis
      xyz="1 0 0" />
    <limit
      effort="0.001"
      velocity="10" />
  </joint>
  

  <!-- Hokuyo Laser -->
  <link name="base_laser">
       <inertial>
      <mass value="1e-5"/>
      <origin xyz="0 0 0" rpy=" 0 0 0"/>
      <inertia ixx="1e-6" ixy="0" ixz="0" iyy="1e-6" iyz="0" izz="1e-6" />
    </inertial>

    <visual name="hokuyo_visual">
      <origin xyz="0 0 0" rpy="0 0 0" />
      <geometry>
        <!-- <mesh filename="$(find bocbot)/meshes/hokuyo.dae"/> -->
        <box size="0.01 0.01 0.01"/>
      </geometry>
    </visual>

    <collision name="hokuyo_colision">
      <origin xyz="0 0 0" rpy="0 0 0" />
      <geometry>
        <box size="0.1 0.1 0.1"/>
      </geometry>
    </collision>
  </link>
     
  
 <joint name="base_laser_joint" type="fixed">
    <axis xyz="0 0 1" />
    <origin xyz="0 0 0.05596" rpy="0 0 0"/>
    <parent link="base_link"/>
    <child link="base_laser"/>
  </joint>

   <gazebo reference="main_body">
    <material>Gazebo/Blue</material>
  </gazebo>
   <gazebo reference="right_wheel">
    <material>Gazebo/Black</material>
  </gazebo>
  <gazebo reference="left_wheel">
    <material>Gazebo/Black</material>
  </gazebo>
  
  </robot>
